<?xml version="1.0"?>
<robot name="agvs" xmlns:xacro="http://www.ros.org/wiki/xacro">
    <xacro:include filename="$(find agv_description)/xacro/agv_base.gazebo.xacro" />

    <!-- PROPERTY LIST -->
    <xacro:property name="M_PI" value="3.14159265359"/>
    <xacro:property name="base_length" value="2"/>
    <xacro:property name="base_width" value="4"/>
    <xacro:property name="base_height" value="0.25"/>
    <xacro:property name="base_mass" value="250.0"/>

    <xacro:property name="imu_size" value="0.001"/>
    <xacro:property name="imu_height" value="0.001"/>

    <xacro:property name="motor_length" value="0.05"/>
    <xacro:property name="motor_width" value="0.05"/>
    <xacro:property name="motor_height" value="0.05"/>
    <xacro:property name="motor_mass" value="20.0"/>

    <xacro:property name="wheel_radius" value="0.05"/>
    <xacro:property name="wheel_width" value="0.05"/>
    <xacro:property name="wheel_mass" value="10.0" />

    <xacro:property name="wheel_joint_damping" value="0.0" />
    <xacro:property name="wheel_joint_friction" value="0.0" />
    <xacro:property name="wheel_joint_effort_limit" value="10.0" />
    <xacro:property name="wheel_joint_velocity_limit" value="20.0" />
    <xacro:property name="wheel_mechanical_reduction" value="1.0" />

    <xacro:property name="steer_joint_damping" value="0.0" />
    <xacro:property name="steer_joint_friction" value="0.0" />
    <xacro:property name="steer_joint_effort_limit" value="10.0" />
    <xacro:property name="steer_joint_velocity_limit" value="10.0" />
    <xacro:property name="motor_wheel_mechanical_reduction" value="1.0" />

    <!-- Macro for whell -->
    <xacro:macro name="wheel" params="prefix x y z">

        <link name="${prefix}_motor_wheel_link">
            <visual>
                <origin xyz="0 0 0" rpy="0 0 0" />
                <!--
                <geometry>
                    <mesh filename="package://agv_description/meshes/motor_wheel.dae" scale="1.0 1.0 1.0"/>
                </geometry>
                -->
                <geometry>
                    <box size="${motor_length} ${motor_width} ${motor_height}" />
                </geometry>
            </visual>

            <gazebo reference="${prefix}_motor_wheel_link">
                <material>Gazebo/Gray</material>
            </gazebo>

            <collision>
                <origin xyz="0 0 0" rpy="0 0 0" /> 
                <!--
                <geometry>
                    <mesh filename="package://agv_description/meshes/motor_wheel.dae" scale="1.0 1.0 1.0"/>
                </geometry>
                -->
                <geometry>
                    <box size="${motor_length} ${motor_width} ${motor_height}" />
                </geometry>
            </collision>

            <xacro:box_inertial mass="${motor_mass}" x="${motor_length}" y="${motor_width}" z="${motor_height}">
                <origin xyz="0 0 0" rpy="0 0 0" />
            </xacro:box_inertial>

        </link>

        <joint name="${prefix}_motor_wheel_joint" type="continuous">
            <origin xyz="${x} ${y} ${z}" rpy="0 0 0"/>
            <parent link="base_link"/>
            <child link="${prefix}_motor_wheel_link"/>
            <axis xyz="0 0 1"/>    
            <limit effort="${steer_joint_effort_limit}" 
                   velocity="${steer_joint_velocity_limit}" 
                   lower="-1.5708" upper="1.5708"/>
            <joint_properties damping="${steer_joint_damping}" friction="{steer_joint_friction}"/>
        </joint>

        <transmission name="${prefix}_motor_wheel_trans">
            <type>transmission_interface/SimpleTransmission</type>
            <joint name="${prefix}_motor_wheel_joint">
                <hardwareInterface>hardware_interface/EffortJointInterface</hardwareInterface>
            </joint>
            <actuator name="${prefix}_motor_joint_motor">
                <hardwareInterface>hardware_interface/EffortJointInterface</hardwareInterface>
                <mechanicalReduction>${motor_wheel_mechanical_reduction}</mechanicalReduction>
            </actuator>
        </transmission>

        <link name="${prefix}_wheel_link">
            <visual>
                <origin xyz="0 0 0" rpy="${0.5 * M_PI} 0 0" />
                <geometry>
                    <cylinder length="${wheel_width}" radius="${wheel_radius}"/>
                <!--
                    <mesh filename="package://agv_description/meshes/agvs_wheel.dae" scale="1.0 1.0 1.0"/>
                -->
                </geometry>
	            <material name="red">
	                <color rgba="0.5 0.1 0.1 1"/>
                </material>
            </visual>

            <collision>
                <origin xyz="0 0 0" rpy="${0.5 * M_PI} 0 0" /> 
                <geometry>
                    <cylinder length="${wheel_width}" radius="${wheel_radius}"/>
	            <!--
                    <mesh filename="package://agv_description/meshes/agvs_wheel.dae" scale="1.0 1.0 1.0"/>
                    <selfCollide>false</selfCollide>
                -->
                </geometry>
                <friction>
                    <ode>
                        <mu>1.0</mu>
                        <mu2>0.0</mu2>
                        <slip1>1.0</slip1>
                        <slip2>1.0</slip2>
                    </ode>
                </friction>
            </collision>

            <xacro:cylinder_inertial mass="${wheel_mass}" radius="${wheel_radius}" length="${wheel_width}">
                <origin xyz="0 0 0" rpy="${0.5 * M_PI} 0 0" />
            </xacro:cylinder_inertial>

        </link>

        <joint name="${prefix}_wheel_joint" type="continuous">
            <origin xyz="0 0 -0.075" rpy="0 0 0"/>
            <parent link="${prefix}_motor_wheel_link"/>
            <child link="${prefix}_wheel_link"/>
            <axis xyz="0 1 0"/>
            <limit effort="${wheel_joint_effort_limit}" velocity="${wheel_joint_velocity_limit}"/>
            <joint_properties damping="${wheel_joint_damping}" friction="{wheel_joint_friction}"/>
        </joint>

    </xacro:macro>

    <xacro:macro name="cylinder_inertial" params="radius length mass *origin">
        <inertial>
        <mass value="${mass}" />
        <xacro:insert_block name="origin" />
        <inertia ixx="${0.0833333 * mass * (3 * radius * radius + length * length)}" ixy="0.0" ixz="0.0"
            iyy="${0.0833333 * mass * (3 * radius * radius + length * length)}" iyz="0.0"
            izz="${0.5 * mass * radius * radius}" />
        </inertial>

    </xacro:macro>

    <xacro:macro name="box_inertial" params="x y z mass *origin">
        <inertial>
        <mass value="${mass}" />
        <xacro:insert_block name="origin" />
        <inertia ixx="${0.0833333 * mass * (y*y + z*z)}" ixy="0.0" ixz="0.0"
            iyy="${0.0833333 * mass * (x*x + z*z)}" iyz="0.0"
            izz="${0.0833333 * mass * (x*x + y*y)}" />
        </inertial>
        
    </xacro:macro>

    <!-- Macro for agv_base -->
    <xacro:macro name="agv_base">
    
        <!-- base_footprint is a fictitious link(frame) that is on the ground right below base_link 
             origin, navigation stack depends on this frame -->
        <link name="base_footprint">
            <visual>
                <origin xyz="0 0 0" rpy="0 0 0" />
                <geometry>
                    <box size="0.001 0.001 0.001" />
                </geometry>
            </visual>
        </link>

        <joint name="base_joint" type="fixed">
            <origin xyz="0 0 0.275" rpy="0 0 0" />        
            <parent link="base_footprint"/>
            <child link="base_link" />
        </joint>

        <link name="base_link">

            <visual>
                <origin xyz="0 0 0" rpy="0 0 0" />
                <geometry>
                    <box size="${base_length} ${base_width} ${base_height}"/>
                </geometry>
            </visual>

            <collision>
                <origin xyz="0 0 0" rpy="0 0 0 " />
                <geometry>
                    <box size="${base_length} ${base_width} ${base_height}"/>
                </geometry>
            </collision>

            <xacro:box_inertial mass="${base_mass}" x="${base_length}" y="${base_width}" z="${base_height}">
                <origin xyz="0 0 0" rpy="0 0 0" />
            </xacro:box_inertial>

        </link>

        <gazebo reference="base_link">
            <material>Gazebo/Gray</material>
        </gazebo>

<!--
        <wheel prefix="front_right" x=" 0.8"  y=" 1.6" z="-0.285"/>
        <wheel prefix="front_left"  x=" 0.8"  y="-1.6" z="-0.285"/>
        <wheel prefix="back_right"  x="-0.8"  y=" 1.6" z="-0.285"/>
        <wheel prefix="back_left"   x="-0.8"  y="-1.6" z="-0.285"/>
-->
        <wheel prefix="front_right" x=" 0.9"  y=" 1.9" z="-0.15"/>
        <wheel prefix="front_left"  x=" 0.9"  y="-1.9" z="-0.15"/>
        <wheel prefix="back_right"  x="-0.9"  y=" 1.9" z="-0.15"/>
        <wheel prefix="back_left"   x="-0.9"  y="-1.9" z="-0.15"/>

    </xacro:macro>
</robot>
